21:30 10-12-2024

# Get in right directory

# Get up to date
Already up to date.

# Run main file

# Upload to Github
[main d2c0159] 213010122024
 1 file changed, 292 insertions(+), 292 deletions(-)
To github.com:LaurensGamet/Somtoday_Madelief.git
   8537d88..d2c0159  main -> main


22:00 10-12-2024

# Get in right directory

# Get up to date
Already up to date.

# Run main file

# Upload to Github
[main 72a8ed6] 220010122024
 1 file changed, 292 insertions(+), 292 deletions(-)
To github.com:LaurensGamet/Somtoday_Madelief.git
   d2c0159..72a8ed6  main -> main


22:30 10-12-2024

# Get in right directory

# Get up to date
Already up to date.

# Run main file

# Upload to Github
[main b460aea] 223010122024
 1 file changed, 292 insertions(+), 292 deletions(-)
To github.com:LaurensGamet/Somtoday_Madelief.git
   72a8ed6..b460aea  main -> main


23:00 10-12-2024

# Get in right directory

# Get up to date
Already up to date.

# Run main file

# Upload to Github
[main bfc285f] 230010122024
 1 file changed, 292 insertions(+), 292 deletions(-)
To github.com:LaurensGamet/Somtoday_Madelief.git
   b460aea..bfc285f  main -> main


23:30 10-12-2024

# Get in right directory

# Get up to date
Already up to date.

# Run main file

# Upload to Github
[main ff3196f] 233010122024
 1 file changed, 292 insertions(+), 292 deletions(-)
To github.com:LaurensGamet/Somtoday_Madelief.git
   bfc285f..ff3196f  main -> main


00:00 11-12-2024

# Get in right directory

# Get up to date
Already up to date.

# Run main file

# Upload to Github
[main e1c50e9] 000011122024
 1 file changed, 292 insertions(+), 292 deletions(-)
To github.com:LaurensGamet/Somtoday_Madelief.git
   ff3196f..e1c50e9  main -> main


00:30 11-12-2024

# Get in right directory

# Get up to date
Already up to date.

# Run main file

# Upload to Github
[main 51cbf2f] 003011122024
 1 file changed, 292 insertions(+), 292 deletions(-)
To github.com:LaurensGamet/Somtoday_Madelief.git
   e1c50e9..51cbf2f  main -> main


01:00 11-12-2024

# Get in right directory

# Get up to date
Already up to date.

# Run main file

# Upload to Github
[main 14d7198] 010011122024
 1 file changed, 292 insertions(+), 292 deletions(-)
To github.com:LaurensGamet/Somtoday_Madelief.git
   51cbf2f..14d7198  main -> main


01:30 11-12-2024

# Get in right directory

# Get up to date
Already up to date.

# Run main file

# Upload to Github
[main c162ead] 013011122024
 1 file changed, 292 insertions(+), 292 deletions(-)
To github.com:LaurensGamet/Somtoday_Madelief.git
   14d7198..c162ead  main -> main


02:00 11-12-2024

# Get in right directory

# Get up to date
Already up to date.

# Run main file

# Upload to Github
[main d1583a8] 020011122024
 1 file changed, 292 insertions(+), 292 deletions(-)
To github.com:LaurensGamet/Somtoday_Madelief.git
   c162ead..d1583a8  main -> main


02:30 11-12-2024

# Get in right directory

# Get up to date
Already up to date.

# Run main file

# Upload to Github
[main fce70eb] 023011122024
 1 file changed, 292 insertions(+), 292 deletions(-)
To github.com:LaurensGamet/Somtoday_Madelief.git
   d1583a8..fce70eb  main -> main


03:00 11-12-2024

# Get in right directory

# Get up to date
Already up to date.

# Run main file

# Upload to Github
[main b0f9612] 030011122024
 1 file changed, 292 insertions(+), 292 deletions(-)
To github.com:LaurensGamet/Somtoday_Madelief.git
   fce70eb..b0f9612  main -> main


03:30 11-12-2024

# Get in right directory

# Get up to date
Already up to date.

# Run main file

# Upload to Github
[main 25e33d9] 033011122024
 1 file changed, 292 insertions(+), 292 deletions(-)
To github.com:LaurensGamet/Somtoday_Madelief.git
   b0f9612..25e33d9  main -> main


04:00 11-12-2024

# Get in right directory

# Get up to date
Already up to date.

# Run main file

# Upload to Github
[main 3dbf394] 040011122024
 1 file changed, 292 insertions(+), 292 deletions(-)
To github.com:LaurensGamet/Somtoday_Madelief.git
   25e33d9..3dbf394  main -> main


04:30 11-12-2024

# Get in right directory

# Get up to date
Already up to date.

# Run main file

# Upload to Github
[main 6d772f4] 043011122024
 1 file changed, 292 insertions(+), 292 deletions(-)
To github.com:LaurensGamet/Somtoday_Madelief.git
   3dbf394..6d772f4  main -> main


05:00 11-12-2024

# Get in right directory

# Get up to date
Already up to date.

# Run main file

# Upload to Github
[main e34af68] 050011122024
 1 file changed, 292 insertions(+), 292 deletions(-)
To github.com:LaurensGamet/Somtoday_Madelief.git
   6d772f4..e34af68  main -> main


05:30 11-12-2024

# Get in right directory

# Get up to date
ssh: Could not resolve hostname github.com: Temporary failure in name resolution
fatal: Could not read from remote repository.

Please make sure you have the correct access rights
and the repository exists.

# Run main file
Traceback (most recent call last):
  File "/usr/lib/python3/dist-packages/urllib3/connection.py", line 169, in _new_conn
    conn = connection.create_connection(
  File "/usr/lib/python3/dist-packages/urllib3/util/connection.py", line 73, in create_connection
    for res in socket.getaddrinfo(host, port, family, socket.SOCK_STREAM):
  File "/usr/lib/python3.9/socket.py", line 953, in getaddrinfo
    for res in _socket.getaddrinfo(host, port, family, type, proto, flags):
socket.gaierror: [Errno -3] Temporary failure in name resolution

During handling of the above exception, another exception occurred:

Traceback (most recent call last):
  File "/usr/lib/python3/dist-packages/urllib3/connectionpool.py", line 699, in urlopen
    httplib_response = self._make_request(
  File "/usr/lib/python3/dist-packages/urllib3/connectionpool.py", line 382, in _make_request
    self._validate_conn(conn)
  File "/usr/lib/python3/dist-packages/urllib3/connectionpool.py", line 1012, in _validate_conn
    conn.connect()
  File "/usr/lib/python3/dist-packages/urllib3/connection.py", line 353, in connect
    conn = self._new_conn()
  File "/usr/lib/python3/dist-packages/urllib3/connection.py", line 181, in _new_conn
    raise NewConnectionError(
urllib3.exceptions.NewConnectionError: <urllib3.connection.HTTPSConnection object at 0xb5eb6be0>: Failed to establish a new connection: [Errno -3] Temporary failure in name resolution

During handling of the above exception, another exception occurred:

Traceback (most recent call last):
  File "/usr/lib/python3/dist-packages/requests/adapters.py", line 439, in send
    resp = conn.urlopen(
  File "/usr/lib/python3/dist-packages/urllib3/connectionpool.py", line 755, in urlopen
    retries = retries.increment(
  File "/usr/lib/python3/dist-packages/urllib3/util/retry.py", line 574, in increment
    raise MaxRetryError(_pool, url, error or ResponseError(cause))
urllib3.exceptions.MaxRetryError: HTTPSConnectionPool(host='api.somtoday.nl', port=443): Max retries exceeded with url: /rest/v1/icalendar/stream/58405be0-5611-4aba-be66-9894a1009f12/c5490491-11eb-4aca-a8f1-ea3f58e75d54 (Caused by NewConnectionError('<urllib3.connection.HTTPSConnection object at 0xb5eb6be0>: Failed to establish a new connection: [Errno -3] Temporary failure in name resolution'))

During handling of the above exception, another exception occurred:

Traceback (most recent call last):
  File "/home/laurens/Somtoday_Madelief/main.py", line 18, in <module>
    r = requests.get(url, allow_redirects=True)
  File "/usr/lib/python3/dist-packages/requests/api.py", line 76, in get
    return request('get', url, params=params, **kwargs)
  File "/usr/lib/python3/dist-packages/requests/api.py", line 61, in request
    return session.request(method=method, url=url, **kwargs)
  File "/usr/lib/python3/dist-packages/requests/sessions.py", line 542, in request
    resp = self.send(prep, **send_kwargs)
  File "/usr/lib/python3/dist-packages/requests/sessions.py", line 655, in send
    r = adapter.send(request, **kwargs)
  File "/usr/lib/python3/dist-packages/requests/adapters.py", line 516, in send
    raise ConnectionError(e, request=request)
requests.exceptions.ConnectionError: HTTPSConnectionPool(host='api.somtoday.nl', port=443): Max retries exceeded with url: /rest/v1/icalendar/stream/58405be0-5611-4aba-be66-9894a1009f12/c5490491-11eb-4aca-a8f1-ea3f58e75d54 (Caused by NewConnectionError('<urllib3.connection.HTTPSConnection object at 0xb5eb6be0>: Failed to establish a new connection: [Errno -3] Temporary failure in name resolution'))

# Upload to Github
[main 1997530] 053011122024
 1 file changed, 3668 deletions(-)
 delete mode 100644 Final-File.ics
ssh: Could not resolve hostname github.com: Temporary failure in name resolution
fatal: Could not read from remote repository.

Please make sure you have the correct access rights
and the repository exists.


06:00 11-12-2024

# Get in right directory

# Get up to date
ssh: Could not resolve hostname github.com: Temporary failure in name resolution
fatal: Could not read from remote repository.

Please make sure you have the correct access rights
and the repository exists.

# Run main file
The file does not exist
Traceback (most recent call last):
  File "/usr/lib/python3/dist-packages/urllib3/connection.py", line 169, in _new_conn
    conn = connection.create_connection(
  File "/usr/lib/python3/dist-packages/urllib3/util/connection.py", line 73, in create_connection
    for res in socket.getaddrinfo(host, port, family, socket.SOCK_STREAM):
  File "/usr/lib/python3.9/socket.py", line 953, in getaddrinfo
    for res in _socket.getaddrinfo(host, port, family, type, proto, flags):
socket.gaierror: [Errno -3] Temporary failure in name resolution

During handling of the above exception, another exception occurred:

Traceback (most recent call last):
  File "/usr/lib/python3/dist-packages/urllib3/connectionpool.py", line 699, in urlopen
    httplib_response = self._make_request(
  File "/usr/lib/python3/dist-packages/urllib3/connectionpool.py", line 382, in _make_request
    self._validate_conn(conn)
  File "/usr/lib/python3/dist-packages/urllib3/connectionpool.py", line 1012, in _validate_conn
    conn.connect()
  File "/usr/lib/python3/dist-packages/urllib3/connection.py", line 353, in connect
    conn = self._new_conn()
  File "/usr/lib/python3/dist-packages/urllib3/connection.py", line 181, in _new_conn
    raise NewConnectionError(
urllib3.exceptions.NewConnectionError: <urllib3.connection.HTTPSConnection object at 0xb5e83be0>: Failed to establish a new connection: [Errno -3] Temporary failure in name resolution

During handling of the above exception, another exception occurred:

Traceback (most recent call last):
  File "/usr/lib/python3/dist-packages/requests/adapters.py", line 439, in send
    resp = conn.urlopen(
  File "/usr/lib/python3/dist-packages/urllib3/connectionpool.py", line 755, in urlopen
    retries = retries.increment(
  File "/usr/lib/python3/dist-packages/urllib3/util/retry.py", line 574, in increment
    raise MaxRetryError(_pool, url, error or ResponseError(cause))
urllib3.exceptions.MaxRetryError: HTTPSConnectionPool(host='api.somtoday.nl', port=443): Max retries exceeded with url: /rest/v1/icalendar/stream/58405be0-5611-4aba-be66-9894a1009f12/c5490491-11eb-4aca-a8f1-ea3f58e75d54 (Caused by NewConnectionError('<urllib3.connection.HTTPSConnection object at 0xb5e83be0>: Failed to establish a new connection: [Errno -3] Temporary failure in name resolution'))

During handling of the above exception, another exception occurred:

Traceback (most recent call last):
  File "/home/laurens/Somtoday_Madelief/main.py", line 18, in <module>
    r = requests.get(url, allow_redirects=True)
  File "/usr/lib/python3/dist-packages/requests/api.py", line 76, in get
    return request('get', url, params=params, **kwargs)
  File "/usr/lib/python3/dist-packages/requests/api.py", line 61, in request
    return session.request(method=method, url=url, **kwargs)
  File "/usr/lib/python3/dist-packages/requests/sessions.py", line 542, in request
    resp = self.send(prep, **send_kwargs)
  File "/usr/lib/python3/dist-packages/requests/sessions.py", line 655, in send
    r = adapter.send(request, **kwargs)
  File "/usr/lib/python3/dist-packages/requests/adapters.py", line 516, in send
    raise ConnectionError(e, request=request)
requests.exceptions.ConnectionError: HTTPSConnectionPool(host='api.somtoday.nl', port=443): Max retries exceeded with url: /rest/v1/icalendar/stream/58405be0-5611-4aba-be66-9894a1009f12/c5490491-11eb-4aca-a8f1-ea3f58e75d54 (Caused by NewConnectionError('<urllib3.connection.HTTPSConnection object at 0xb5e83be0>: Failed to establish a new connection: [Errno -3] Temporary failure in name resolution'))

# Upload to Github
On branch main
Your branch is ahead of 'origin/main' by 1 commit.
  (use "git push" to publish your local commits)

nothing to commit, working tree clean
ssh: Could not resolve hostname github.com: Temporary failure in name resolution
fatal: Could not read from remote repository.

Please make sure you have the correct access rights
and the repository exists.


06:30 11-12-2024

# Get in right directory

# Get up to date
ssh: Could not resolve hostname github.com: Temporary failure in name resolution
fatal: Could not read from remote repository.

Please make sure you have the correct access rights
and the repository exists.

# Run main file
The file does not exist
Traceback (most recent call last):
  File "/usr/lib/python3/dist-packages/urllib3/connection.py", line 169, in _new_conn
    conn = connection.create_connection(
  File "/usr/lib/python3/dist-packages/urllib3/util/connection.py", line 73, in create_connection
    for res in socket.getaddrinfo(host, port, family, socket.SOCK_STREAM):
  File "/usr/lib/python3.9/socket.py", line 953, in getaddrinfo
    for res in _socket.getaddrinfo(host, port, family, type, proto, flags):
socket.gaierror: [Errno -3] Temporary failure in name resolution

During handling of the above exception, another exception occurred:

Traceback (most recent call last):
  File "/usr/lib/python3/dist-packages/urllib3/connectionpool.py", line 699, in urlopen
    httplib_response = self._make_request(
  File "/usr/lib/python3/dist-packages/urllib3/connectionpool.py", line 382, in _make_request
    self._validate_conn(conn)
  File "/usr/lib/python3/dist-packages/urllib3/connectionpool.py", line 1012, in _validate_conn
    conn.connect()
  File "/usr/lib/python3/dist-packages/urllib3/connection.py", line 353, in connect
    conn = self._new_conn()
  File "/usr/lib/python3/dist-packages/urllib3/connection.py", line 181, in _new_conn
    raise NewConnectionError(
urllib3.exceptions.NewConnectionError: <urllib3.connection.HTTPSConnection object at 0xb5eadbe0>: Failed to establish a new connection: [Errno -3] Temporary failure in name resolution

During handling of the above exception, another exception occurred:

Traceback (most recent call last):
  File "/usr/lib/python3/dist-packages/requests/adapters.py", line 439, in send
    resp = conn.urlopen(
  File "/usr/lib/python3/dist-packages/urllib3/connectionpool.py", line 755, in urlopen
    retries = retries.increment(
  File "/usr/lib/python3/dist-packages/urllib3/util/retry.py", line 574, in increment
    raise MaxRetryError(_pool, url, error or ResponseError(cause))
urllib3.exceptions.MaxRetryError: HTTPSConnectionPool(host='api.somtoday.nl', port=443): Max retries exceeded with url: /rest/v1/icalendar/stream/58405be0-5611-4aba-be66-9894a1009f12/c5490491-11eb-4aca-a8f1-ea3f58e75d54 (Caused by NewConnectionError('<urllib3.connection.HTTPSConnection object at 0xb5eadbe0>: Failed to establish a new connection: [Errno -3] Temporary failure in name resolution'))

During handling of the above exception, another exception occurred:

Traceback (most recent call last):
  File "/home/laurens/Somtoday_Madelief/main.py", line 18, in <module>
    r = requests.get(url, allow_redirects=True)
  File "/usr/lib/python3/dist-packages/requests/api.py", line 76, in get
    return request('get', url, params=params, **kwargs)
  File "/usr/lib/python3/dist-packages/requests/api.py", line 61, in request
    return session.request(method=method, url=url, **kwargs)
  File "/usr/lib/python3/dist-packages/requests/sessions.py", line 542, in request
    resp = self.send(prep, **send_kwargs)
  File "/usr/lib/python3/dist-packages/requests/sessions.py", line 655, in send
    r = adapter.send(request, **kwargs)
  File "/usr/lib/python3/dist-packages/requests/adapters.py", line 516, in send
    raise ConnectionError(e, request=request)
requests.exceptions.ConnectionError: HTTPSConnectionPool(host='api.somtoday.nl', port=443): Max retries exceeded with url: /rest/v1/icalendar/stream/58405be0-5611-4aba-be66-9894a1009f12/c5490491-11eb-4aca-a8f1-ea3f58e75d54 (Caused by NewConnectionError('<urllib3.connection.HTTPSConnection object at 0xb5eadbe0>: Failed to establish a new connection: [Errno -3] Temporary failure in name resolution'))

# Upload to Github
On branch main
Your branch is ahead of 'origin/main' by 1 commit.
  (use "git push" to publish your local commits)

nothing to commit, working tree clean
ssh: Could not resolve hostname github.com: Temporary failure in name resolution
fatal: Could not read from remote repository.

Please make sure you have the correct access rights
and the repository exists.


07:00 11-12-2024

# Get in right directory

# Get up to date
ssh: Could not resolve hostname github.com: Temporary failure in name resolution
fatal: Could not read from remote repository.

Please make sure you have the correct access rights
and the repository exists.

# Run main file
The file does not exist
Traceback (most recent call last):
  File "/usr/lib/python3/dist-packages/urllib3/connection.py", line 169, in _new_conn
    conn = connection.create_connection(
  File "/usr/lib/python3/dist-packages/urllib3/util/connection.py", line 73, in create_connection
    for res in socket.getaddrinfo(host, port, family, socket.SOCK_STREAM):
  File "/usr/lib/python3.9/socket.py", line 953, in getaddrinfo
    for res in _socket.getaddrinfo(host, port, family, type, proto, flags):
socket.gaierror: [Errno -3] Temporary failure in name resolution

During handling of the above exception, another exception occurred:

Traceback (most recent call last):
  File "/usr/lib/python3/dist-packages/urllib3/connectionpool.py", line 699, in urlopen
    httplib_response = self._make_request(
  File "/usr/lib/python3/dist-packages/urllib3/connectionpool.py", line 382, in _make_request
    self._validate_conn(conn)
  File "/usr/lib/python3/dist-packages/urllib3/connectionpool.py", line 1012, in _validate_conn
    conn.connect()
  File "/usr/lib/python3/dist-packages/urllib3/connection.py", line 353, in connect
    conn = self._new_conn()
  File "/usr/lib/python3/dist-packages/urllib3/connection.py", line 181, in _new_conn
    raise NewConnectionError(
urllib3.exceptions.NewConnectionError: <urllib3.connection.HTTPSConnection object at 0xb5eb9be0>: Failed to establish a new connection: [Errno -3] Temporary failure in name resolution

During handling of the above exception, another exception occurred:

Traceback (most recent call last):
  File "/usr/lib/python3/dist-packages/requests/adapters.py", line 439, in send
    resp = conn.urlopen(
  File "/usr/lib/python3/dist-packages/urllib3/connectionpool.py", line 755, in urlopen
    retries = retries.increment(
  File "/usr/lib/python3/dist-packages/urllib3/util/retry.py", line 574, in increment
    raise MaxRetryError(_pool, url, error or ResponseError(cause))
urllib3.exceptions.MaxRetryError: HTTPSConnectionPool(host='api.somtoday.nl', port=443): Max retries exceeded with url: /rest/v1/icalendar/stream/58405be0-5611-4aba-be66-9894a1009f12/c5490491-11eb-4aca-a8f1-ea3f58e75d54 (Caused by NewConnectionError('<urllib3.connection.HTTPSConnection object at 0xb5eb9be0>: Failed to establish a new connection: [Errno -3] Temporary failure in name resolution'))

During handling of the above exception, another exception occurred:

Traceback (most recent call last):
  File "/home/laurens/Somtoday_Madelief/main.py", line 18, in <module>
    r = requests.get(url, allow_redirects=True)
  File "/usr/lib/python3/dist-packages/requests/api.py", line 76, in get
    return request('get', url, params=params, **kwargs)
  File "/usr/lib/python3/dist-packages/requests/api.py", line 61, in request
    return session.request(method=method, url=url, **kwargs)
  File "/usr/lib/python3/dist-packages/requests/sessions.py", line 542, in request
    resp = self.send(prep, **send_kwargs)
  File "/usr/lib/python3/dist-packages/requests/sessions.py", line 655, in send
    r = adapter.send(request, **kwargs)
  File "/usr/lib/python3/dist-packages/requests/adapters.py", line 516, in send
    raise ConnectionError(e, request=request)
requests.exceptions.ConnectionError: HTTPSConnectionPool(host='api.somtoday.nl', port=443): Max retries exceeded with url: /rest/v1/icalendar/stream/58405be0-5611-4aba-be66-9894a1009f12/c5490491-11eb-4aca-a8f1-ea3f58e75d54 (Caused by NewConnectionError('<urllib3.connection.HTTPSConnection object at 0xb5eb9be0>: Failed to establish a new connection: [Errno -3] Temporary failure in name resolution'))

# Upload to Github
On branch main
Your branch is ahead of 'origin/main' by 1 commit.
  (use "git push" to publish your local commits)

nothing to commit, working tree clean
ssh: Could not resolve hostname github.com: Temporary failure in name resolution
fatal: Could not read from remote repository.

Please make sure you have the correct access rights
and the repository exists.


07:30 11-12-2024

# Get in right directory

# Get up to date
Already up to date.

# Run main file
The file does not exist

# Upload to Github
